Workbook

Sheet TablasInformes (1)
B1: SparklingCo
A2: 0 | B2: Valor de la compania
C3: Total Compania | E3: Variacion
C4: 2028 | D4: 2027 | E4: Diferencia | F4: %
B5: GlobalBiz | C5: 5406 | D5: 5315 | E5: 91 | F5: 0.017
B6: FreshMarket | C6: 5463 | D6: 5279 | E6: 184 | F6: 0.035
B7: SparklingCo | C7: 5104 | D7: 4815 | E7: 289 | F7: 0.06
B8: QualityMax | C8: 5344 | D8: 5079 | E8: 265 | F8: 0.052
B9: Drink2Go | C9: 4697 | D9: 5314 | E9: -617 | F9: -0.116
B10: Media | C10: 5203 | D10: 5161 | E10: 42 | F10: 0.008
A12: Comparativa Valor Compania. 1
A13: 1 | B13: 2023 | C13: 2024 | D13: 2025 | E13: 2026 | F13: 2027 | G13: 2028
A14: GlobalBiz | B14: 4118.8 | C14: 4491.6 | D14: 4646 | E14: 5061 | F14: 5315.5 | G14: 5406.1
A15: FreshMarket | B15: 4118.8 | C15: 4392.1 | D15: 4736.3 | E15: 5139.4 | F15: 5279 | G15: 5462.8
A16: SparklingCo | B16: 4118.8 | C16: 3910.9 | D16: 3825.2 | E16: 4384.7 | F16: 4815.2 | G16: 5103.8
A17: QualityMax | B17: 4118.8 | C17: 4073.1 | D17: 4470.4 | E17: 4796.8 | F17: 5079.4 | G17: 5344.4
A18: Drink2Go | B18: 4118.8 | C18: 4538 | D18: 5089.3 | E18: 5223.1 | F18: 5314.2 | G18: 4696.8
A21: Analisis valor compania.
A22: Ponderacion media parametros.
A23: 2 | B23: 2023 | C23: 2024 | D23: 2025 | E23: 2026 | F23: 2027 | G23: 2028
B24: Ponderacion Media | C24: Ponderacion Media | D24: Ponderacion Media | E24: Ponderacion Media | F24: Ponderacion Media | G24: Ponderacion Media
A25: Resultados Economicos | B25: 1925 | C25: 2056 | D25: 2301 | E25: 2587 | F25: 2779 | G25: 2769
A26: Patrimonio - Solvencia | B26: 272 | C26: 245 | D26: 247 | E26: 275 | F26: 278 | G26: 278
A27: Participacion de Mercado | B27: 458 | C27: 462 | D27: 467 | E27: 470 | F27: 478 | G27: 482
A28: Valor de Marca | B28: 408 | C28: 444 | D28: 435 | E28: 443 | F28: 441 | G28: 462
A29: Valor de Producto | B29: 495 | C29: 500 | D29: 504 | E29: 513 | F29: 521 | G29: 527
A30: Cobertura de Distribucion | B30: 296 | C30: 295 | D30: 296 | E30: 295 | F30: 298 | G30: 300
A31: Tecnologia Industrial | B31: 264 | C31: 280 | D31: 304 | E31: 337 | F31: 365 | G31: 386
A34: Variacion Valor Compañia
B35: Primer año | C35: Diferencia 1 | D35: Diferencia 2 | E35: Diferencia 3 | F35: Diferencia 4 | G35: Diferencia 5 | H35: Ano actual
A36: GlobalBiz | B36: 4119 | C36: 373 | D36: 154 | E36: 415 | F36: 254 | G36: 91 | H36: 5406
A37: FreshMarket | B37: 4119 | C37: 273 | D37: 344 | E37: 403 | F37: 140 | G37: 184 | H37: 5463
A38: SparklingCo | B38: 4119 | C38: -208 | D38: -86 | E38: 559 | F38: 431 | G38: 289 | H38: 5104
A39: QualityMax | B39: 4119 | C39: -46 | D39: 397 | E39: 326 | F39: 283 | G39: 265 | H39: 5344
A40: Drink2Go | B40: 4119 | C40: 419 | D40: 551 | E40: 134 | F40: 91 | G40: -617 | H40: 4697
A42: Analisis valor compania. Comparativa.
A43: 3 | B43: GlobalBiz | C43: FreshMarket | D43: SparklingCo | E43: QualityMax | F43: Drink2Go
A44: Resultados Economicos | B44: 3021 | C44: 3056 | D44: 2626 | E44: 2984 | F44: 2156
A45: Patrimonio - Solvencia | B45: 229 | C45: 229 | D45: 358 | E45: 309 | F45: 263
A46: Participacion de Mercado | B46: 501 | C46: 467 | D46: 472 | E46: 477 | F46: 491
...

Sheet 1
A1: 0
A2: Valor de la compania
B3: Total Compania | D3: Variacion
B4: Año T | C4: Año T-1 | D4: Diferencia | E4: % Variacion
A5: GlobalBiz | B5: =+'TablasInformes (1)'!C5 -> 5406 | C5: =+'TablasInformes (1)'!D5 -> 5315 | D5: =+'TablasInformes (1)'!E5 -> 91 | E5: =+'TablasInformes (1)'!F5 -> 0.017
A6: FreshMarket | B6: =+'TablasInformes (1)'!C6 -> 5463 | C6: =+'TablasInformes (1)'!D6 -> 5279 | D6: =+'TablasInformes (1)'!E6 -> 184 | E6: =+'TablasInformes (1)'!F6 -> 0.035
A7: SparklingCo | B7: =+'TablasInformes (1)'!C7 -> 5104 | C7: =+'TablasInformes (1)'!D7 -> 4815 | D7: =+'TablasInformes (1)'!E7 -> 289 | E7: =+'TablasInformes (1)'!F7 -> 0.06
A8: QualityMax | B8: =+'TablasInformes (1)'!C8 -> 5344 | C8: =+'TablasInformes (1)'!D8 -> 5079 | D8: =+'TablasInformes (1)'!E8 -> 265 | E8: =+'TablasInformes (1)'!F8 -> 0.052
A9: Drink2Go | B9: =+'TablasInformes (1)'!C9 -> 4697 | C9: =+'TablasInformes (1)'!D9 -> 5314 | D9: =+'TablasInformes (1)'!E9 -> -617 | E9: =+'TablasInformes (1)'!F9 -> -0.116
A10: Media | B10: =+'TablasInformes (1)'!C10 -> 5203 | C10: =+'TablasInformes (1)'!D10 -> 5161 | D10: =+'TablasInformes (1)'!E10 -> 42 | E10: =+'TablasInformes (1)'!F10 -> 0.008
A25: 1
A26: Comparativa Valor Compania.
B27: =+'TablasInformes (1)'!B13 -> 2023 | C27: =+'TablasInformes (1)'!C13 -> 2024 | D27: =+'TablasInformes (1)'!D13 -> 2025 | E27: =+'TablasInformes (1)'!E13 -> 2026 | F27: =+'TablasInformes (1)'!F13 -> 2027 | G27: =+'TablasInformes (1)'!G13 -> 2028
A28: =+'TablasInformes (1)'!A14 -> GlobalBiz | B28: =+'TablasInformes (1)'!B14 -> 4118.8 | C28: =+'TablasInformes (1)'!C14 -> 4491.6 | D28: =+'TablasInformes (1)'!D14 -> 4646 | E28: =+'TablasInformes (1)'!E14 -> 5061 | F28: =+'TablasInformes (1)'!F14 -> 5315.5 | G28: =+'TablasInformes (1)'!G14 -> 5406.1
A29: =+'TablasInformes (1)'!A15 -> FreshMarket | B29: =+'TablasInformes (1)'!B15 -> 4118.8 | C29: =+'TablasInformes (1)'!C15 -> 4392.1 | D29: =+'TablasInformes (1)'!D15 -> 4736.3 | E29: =+'TablasInformes (1)'!E15 -> 5139.4 | F29: =+'TablasInformes (1)'!F15 -> 5279 | G29: =+'TablasInformes (1)'!G15 -> 5462.8
A30: =+'TablasInformes (1)'!A16 -> SparklingCo | B30: =+'TablasInformes (1)'!B16 -> 4118.8 | C30: =+'TablasInformes (1)'!C16 -> 3910.9 | D30: =+'TablasInformes (1)'!D16 -> 3825.2 | E30: =+'TablasInformes (1)'!E16 -> 4384.7 | F30: =+'TablasInformes (1)'!F16 -> 4815.2 | G30: =+'TablasInformes (1)'!G16 -> 5103.8
A31: =+'TablasInformes (1)'!A17 -> QualityMax | B31: =+'TablasInformes (1)'!B17 -> 4118.8 | C31: =+'TablasInformes (1)'!C17 -> 4073.1 | D31: =+'TablasInformes (1)'!D17 -> 4470.4 | E31: =+'TablasInformes (1)'!E17 -> 4796.8 | F31: =+'TablasInformes (1)'!F17 -> 5079.4 | G31: =+'TablasInformes (1)'!G17 -> 5344.4
B32: =+'TablasInformes (1)'!B18 -> 4118.8 | C32: =+'TablasInformes (1)'!C18 -> 4538 | D32: =+'TablasInformes (1)'!D18 -> 5089.3 | E32: =+'TablasInformes (1)'!E18 -> 5223.1 | F32: =+'TablasInformes (1)'!F18 -> 5314.2 | G32: =+'TablasInformes (1)'!G18 -> 4696.8
C33: =+B32*1.07 -> 4407.116 | D33: =+C32*1.07 -> 4855.66 | E33: =+D32*1.07 -> 5445.551 | F33: =+E32*1.07 -> 5588.717 | G33: =+F32*1.07 -> 5686.194
B34: =+'TablasInformes (1)'!A18 -> Drink2Go | C34: =(C32-B32)/B32 -> 0.10177722 | D34: =(D32-C32)/C32 -> 0.12148524 | E34: =(E32-D32)/D32 -> 0.026290453 | F34: =(F32-E32)/E32 -> 0.017441749 | G34: =(G32-F32)/F32 -> -0.11617929
E35: =SUM(C34:G34)/5 -> 0.030163072
B38: GlobalBiz | C38: FreshMarket | D38: SparklingCo | E38: QualityMax | F38: Drink2Go
A39: =+B27 -> 2023 | B39: =+B28 -> 4118.8 | C39: =+B29 -> 4118.8 | D39: =+B30 -> 4118.8 | E39: =+B31 -> 4118.8 | F39: =+B32 -> 4118.8
A40: =+C27 -> 2024 | B40: =+C28 -> 4491.6 | C40: =+C29 -> 4392.1 | D40: =+C30 -> 3910.9 | E40: =+C31 -> 4073.1 | F40: =+C32 -> 4538
A41: =+D27 -> 2025 | B41: =+D28 -> 4646 | C41: =+D29 -> 4736.3 | D41: =+D30 -> 3825.2 | E41: =+D31 -> 4470.4 | F41: =+D32 -> 5089.3
A42: =+E27 -> 2026 | B42: =+E28 -> 5061 | C42: =+E29 -> 5139.4 | D42: =+E30 -> 4384.7 | E42: =+E31 -> 4796.8 | F42: =+E32 -> 5223.1
A43: =+F27 -> 2027 | B43: =+F28 -> 5315.5 | C43: =+F29 -> 5279 | D43: =+F30 -> 4815.2 | E43: =+F31 -> 5079.4 | F43: =+F32 -> 5314.2
A44: =+G27 -> 2028 | B44: =+G28 -> 5406.1 | C44: =+G29 -> 5462.8 | D44: =+G30 -> 5103.8 | E44: =+G31 -> 5344.4 | F44: =+G32 -> 4696.8
B47: =+B38 -> GlobalBiz
A48: =+A39 -> 2023 | B48: =+B39 -> 4118.8
A49: =+A40 -> 2024 | B49: =+B40 -> 4491.6
A50: =+A41 -> 2025 | B50: =+B41 -> 4646
A51: =+A42 -> 2026 | B51: =+B42 -> 5061
A52: =+A43 -> 2027 | B52: =+B43 -> 5315.5
A53: =+A44 -> 2028 | B53: =+B44 -> 5406.1
B62: FreshMarket
A63: =+A48 -> 2023 | B63: =+C39 -> 4118.8
A64: =+A49 -> 2024 | B64: =+C40 -> 4392.1
A65: =+A50 -> 2025 | B65: =+C41 -> 4736.3
A66: =+A51 -> 2026 | B66: =+C42 -> 5139.4
...

Sheet 2
A1: 2
A2: Analisis valor compania.
A3: Ponderacion Media de los parametros.
B4: =+'TablasInformes (1)'!B23 -> 2023 | C4: =+'TablasInformes (1)'!C23 -> 2024 | D4: =+'TablasInformes (1)'!D23 -> 2025 | E4: =+'TablasInformes (1)'!E23 -> 2026 | F4: =+'TablasInformes (1)'!F23 -> 2027 | G4: =+'TablasInformes (1)'!G23 -> 2028 | H4: COMPORTAMIENTO GRÁFICO
B5: =+'TablasInformes (1)'!B24 -> Ponderacion Media | C5: =+'TablasInformes (1)'!C24 -> Ponderacion Media | D5: =+'TablasInformes (1)'!D24 -> Ponderacion Media | E5: =+'TablasInformes (1)'!E24 -> Ponderacion Media | F5: =+'TablasInformes (1)'!F24 -> Ponderacion Media | G5: =+'TablasInformes (1)'!G24 -> Ponderacion Media
A6: Resultados Economicos | B6: =+'TablasInformes (1)'!B25 -> 1925 | C6: =+'TablasInformes (1)'!C25 -> 2056 | D6: =+'TablasInformes (1)'!D25 -> 2301 | E6: =+'TablasInformes (1)'!E25 -> 2587 | F6: =+'TablasInformes (1)'!F25 -> 2779 | G6: =+'TablasInformes (1)'!G25 -> 2769
A7: Patrimonio - Solvencia | B7: =+'TablasInformes (1)'!B26 -> 272 | C7: =+'TablasInformes (1)'!C26 -> 245 | D7: =+'TablasInformes (1)'!D26 -> 247 | E7: =+'TablasInformes (1)'!E26 -> 275 | F7: =+'TablasInformes (1)'!F26 -> 278 | G7: =+'TablasInformes (1)'!G26 -> 278
A8: Participacion de Mercado | B8: =+'TablasInformes (1)'!B27 -> 458 | C8: =+'TablasInformes (1)'!C27 -> 462 | D8: =+'TablasInformes (1)'!D27 -> 467 | E8: =+'TablasInformes (1)'!E27 -> 470 | F8: =+'TablasInformes (1)'!F27 -> 478 | G8: =+'TablasInformes (1)'!G27 -> 482
A9: Valor de Marca | B9: =+'TablasInformes (1)'!B28 -> 408 | C9: =+'TablasInformes (1)'!C28 -> 444 | D9: =+'TablasInformes (1)'!D28 -> 435 | E9: =+'TablasInformes (1)'!E28 -> 443 | F9: =+'TablasInformes (1)'!F28 -> 441 | G9: =+'TablasInformes (1)'!G28 -> 462
A10: Valor de Producto | B10: =+'TablasInformes (1)'!B29 -> 495 | C10: =+'TablasInformes (1)'!C29 -> 500 | D10: =+'TablasInformes (1)'!D29 -> 504 | E10: =+'TablasInformes (1)'!E29 -> 513 | F10: =+'TablasInformes (1)'!F29 -> 521 | G10: =+'TablasInformes (1)'!G29 -> 527
A11: Cobertura de Distribucion | B11: =+'TablasInformes (1)'!B30 -> 296 | C11: =+'TablasInformes (1)'!C30 -> 295 | D11: =+'TablasInformes (1)'!D30 -> 296 | E11: =+'TablasInformes (1)'!E30 -> 295 | F11: =+'TablasInformes (1)'!F30 -> 298 | G11: =+'TablasInformes (1)'!G30 -> 300
A12: Tecnologia Industrial | B12: =+'TablasInformes (1)'!B31 -> 264 | C12: =+'TablasInformes (1)'!C31 -> 280 | D12: =+'TablasInformes (1)'!D31 -> 304 | E12: =+'TablasInformes (1)'!E31 -> 337 | F12: =+'TablasInformes (1)'!F31 -> 365 | G12: =+'TablasInformes (1)'!G31 -> 386
A15: Ge | B15: Resultados Economicos
A16: =+B4 -> 2023 | B16: =+B6 -> 1925 | D16: 0.076425596
A17: =+C4 -> 2024 | B17: =+C6 -> 2056 | C17: =(B17-B16)/B16 -> 0.068051948 | D17: 0.076425596
A18: =+D4 -> 2025 | B18: =+D6 -> 2301 | C18: =(B18-B17)/B17 -> 0.11916342 | D18: 0.076425596
A19: =+E4 -> 2026 | B19: =+E6 -> 2587 | C19: =(B19-B18)/B18 -> 0.12429379 | D19: 0.076425596
A20: =+F4 -> 2027 | B20: =+F6 -> 2779 | C20: =(B20-B19)/B19 -> 0.07421724 | D20: 0.076425596
A21: =+G4 -> 2028 | B21: =+G6 -> 2769 | C21: =(B21-B20)/B20 -> -0.0035984167 | D21: 0.076425596
C22: =AVERAGE(C17:C21) -> 0.076425596
B24: =+A7 -> Patrimonio - Solvencia
A25: =+A16 -> 2023 | B25: =+B7 -> 272
A26: =+A17 -> 2024 | B26: =+C7 -> 245
A27: =+A18 -> 2025 | B27: =+D7 -> 247
A28: =+A19 -> 2026 | B28: =+E7 -> 275
A29: =+A20 -> 2027 | B29: =+F7 -> 278
A30: =+A21 -> 2028 | B30: =+G7 -> 278
B33: =+A8 -> Participacion de Mercado
A34: =+A25 -> 2023 | B34: =+B8 -> 458
A35: =+A26 -> 2024 | B35: =+C8 -> 462
A36: =+A27 -> 2025 | B36: =+D8 -> 467
A37: =+A28 -> 2026 | B37: =+E8 -> 470
A38: =+A29 -> 2027 | B38: =+F8 -> 478
A39: =+A30 -> 2028 | B39: =+G8 -> 482
B42: =+A9 -> Valor de Marca
A43: =+A34 -> 2023 | B43: =+B9 -> 408
A44: =+A35 -> 2024 | B44: =+C9 -> 444
A45: =+A36 -> 2025 | B45: =+D9 -> 435
A46: =+A37 -> 2026 | B46: =+E9 -> 443
A47: =+A38 -> 2027 | B47: =+F9 -> 441
...

Sheet 3
A1: 3
A2: Analisis valor compania. Comparativa.
B3: =+'TablasInformes (1)'!B43 -> GlobalBiz | C3: =+'TablasInformes (1)'!C43 -> FreshMarket | D3: =+'TablasInformes (1)'!D43 -> SparklingCo | E3: =+'TablasInformes (1)'!E43 -> QualityMax | F3: =+'TablasInformes (1)'!F43 -> Drink2Go | M3: =+A4 -> Resultados Economicos
A4: Resultados Economicos | B4: =+'TablasInformes (1)'!B44 -> 3021 | C4: =+'TablasInformes (1)'!C44 -> 3056 | D4: =+'TablasInformes (1)'!D44 -> 2626 | E4: =+'TablasInformes (1)'!E44 -> 2984 | F4: =+'TablasInformes (1)'!F44 -> 2156 | L4: =+B3 -> GlobalBiz | M4: =+B4 -> 3021
A5: Patrimonio - Solvencia | B5: =+'TablasInformes (1)'!B45 -> 229 | C5: =+'TablasInformes (1)'!C45 -> 229 | D5: =+'TablasInformes (1)'!D45 -> 358 | E5: =+'TablasInformes (1)'!E45 -> 309 | F5: =+'TablasInformes (1)'!F45 -> 263 | L5: =+C3 -> FreshMarket | M5: =+C4 -> 3056
A6: Participacion de Mercado | B6: =+'TablasInformes (1)'!B46 -> 501 | C6: =+'TablasInformes (1)'!C46 -> 467 | D6: =+'TablasInformes (1)'!D46 -> 472 | E6: =+'TablasInformes (1)'!E46 -> 477 | F6: =+'TablasInformes (1)'!F46 -> 491 | L6: =+D3 -> SparklingCo | M6: =+D4 -> 2626
A7: Valor de Marca | B7: =+'TablasInformes (1)'!B47 -> 448 | C7: =+'TablasInformes (1)'!C47 -> 525 | D7: =+'TablasInformes (1)'!D47 -> 405 | E7: =+'TablasInformes (1)'!E47 -> 405 | F7: =+'TablasInformes (1)'!F47 -> 525 | L7: =+E3 -> QualityMax | M7: =+E4 -> 2984
A8: Valor de Producto | B8: =+'TablasInformes (1)'!B48 -> 539 | C8: =+'TablasInformes (1)'!C48 -> 529 | D8: =+'TablasInformes (1)'!D48 -> 520 | E8: =+'TablasInformes (1)'!E48 -> 520 | F8: =+'TablasInformes (1)'!F48 -> 529 | L8: =+F3 -> Drink2Go | M8: =+F4 -> 2156
A9: Capacidad - Cobertura | B9: =+'TablasInformes (1)'!B49 -> 273 | C9: =+'TablasInformes (1)'!C49 -> 305 | D9: =+'TablasInformes (1)'!D49 -> 327 | E9: =+'TablasInformes (1)'!E49 -> 254 | F9: =+'TablasInformes (1)'!F49 -> 337
A10: Desarrollo Tecno - Eficiencia Prod | B10: =+'TablasInformes (1)'!B50 -> 395 | C10: =+'TablasInformes (1)'!C50 -> 352 | D10: =+'TablasInformes (1)'!D50 -> 395 | E10: =+'TablasInformes (1)'!E50 -> 395 | F10: =+'TablasInformes (1)'!F50 -> 395
A11: No Decision | B11: =+'TablasInformes (1)'!B51 -> 100 | C11: =+'TablasInformes (1)'!C51 -> 100 | D11: =+'TablasInformes (1)'!D51 -> 100 | E11: =+'TablasInformes (1)'!E51 -> 100 | F11: =+'TablasInformes (1)'!F51 -> 100
A12: Valor Compania | B12: =+'TablasInformes (1)'!B52 -> 5406 | C12: =+'TablasInformes (1)'!C52 -> 5463 | D12: =+'TablasInformes (1)'!D52 -> 5104 | E12: =+'TablasInformes (1)'!E52 -> 5344 | F12: =+'TablasInformes (1)'!F52 -> 4697
B15: GlobalBiz
A16: Resultados Economicos | B16: =+B4 -> 3021 | M16: =+A5 -> Patrimonio - Solvencia
A17: Patrimonio - Solvencia | B17: =+B5 -> 229 | L17: =+B3 -> GlobalBiz | M17: =+B5 -> 229
A18: Participacion de Mercado | B18: =+B6 -> 501 | L18: =+C3 -> FreshMarket | M18: =+C5 -> 229
A19: Valor de Marca | B19: =+B7 -> 448 | L19: =+D3 -> SparklingCo | M19: =+D5 -> 358
A20: Valor de Producto | B20: =+B8 -> 539 | L20: =+E3 -> QualityMax | M20: =+E5 -> 309
A21: Capacidad - Cobertura | B21: =+B9 -> 273 | L21: =+F3 -> Drink2Go | M21: =+F5 -> 263
A22: Desarrollo Tecno - Eficiencia Prod | B22: =+B10 -> 395
A23: No Decision | B23: =+B11 -> 100
A24: Valor Compania | B24: =+B12 -> 5406
B27: FreshMarket
A28: Resultados Economicos | B28: =+C4 -> 3056
A29: Patrimonio - Solvencia | B29: =+C5 -> 229
A30: Participacion de Mercado | B30: =+C6 -> 467 | M30: =+A6 -> Participacion de Mercado
A31: Valor de Marca | B31: =+C7 -> 525 | L31: GlobalBiz | M31: =+B6 -> 501
A32: Valor de Producto | B32: =+C8 -> 529 | L32: FreshMarket | M32: =+C6 -> 467
A33: Capacidad - Cobertura | B33: =+C9 -> 305 | L33: SparklingCo | M33: =+D6 -> 472
A34: Desarrollo Tecno - Eficiencia Prod | B34: =+C10 -> 352 | L34: QualityMax | M34: =+E6 -> 477
A35: No Decision | B35: =+C11 -> 100 | L35: Drink2Go | M35: =+F6 -> 491
A36: Valor Compania | B36: =+C12 -> 5463
B39: SparklingCo
A40: Resultados Economicos | B40: 2626
A41: Patrimonio - Solvencia | B41: 358
A42: Participacion de Mercado | B42: 472
A43: Valor de Marca | B43: 405
A44: Valor de Producto | B44: 520 | M44: =+A7 -> Valor de Marca
A45: Capacidad - Cobertura | B45: 327 | L45: GlobalBiz | M45: =+B7 -> 448
A46: Desarrollo Tecno - Eficiencia Prod | B46: 395 | L46: FreshMarket | M46: =+C7 -> 525
...

Sheet 4
A1: 4
A2: Valores del Escenario
C3: Periodo Actual | D3: T+1 | E3: T+2
A4: Indice de Precios al Consumo | B4: España | C4: =+'TablasInformes (1)'!C57 -> 30 | D4: =+'TablasInformes (1)'!D57 -> 26 | E4: =+'TablasInformes (1)'!E57 -> 24
B5: Portugal | C5: =+'TablasInformes (1)'!C58 -> 25 | D5: =+'TablasInformes (1)'!D58 -> 23 | E5: =+'TablasInformes (1)'!E58 -> 21
B6: Francia | C6: =+'TablasInformes (1)'!C59 -> 26 | D6: =+'TablasInformes (1)'!D59 -> 19 | E6: =+'TablasInformes (1)'!E59 -> 20
B7: Italia | C7: =+'TablasInformes (1)'!C60 -> 27 | D7: =+'TablasInformes (1)'!D60 -> 22 | E7: =+'TablasInformes (1)'!E60 -> 24
B8: Centro Europa | C8: =+'TablasInformes (1)'!C61 -> 11 | D8: =+'TablasInformes (1)'!D61 -> 12 | E8: =+'TablasInformes (1)'!E61 -> 18
B9: Polonia | C9: =+'TablasInformes (1)'!C62 -> 26 | D9: =+'TablasInformes (1)'!D62 -> 19 | E9: =+'TablasInformes (1)'!E62 -> 16
B10: Mexico | C10: =+'TablasInformes (1)'!C63 -> 41 | D10: =+'TablasInformes (1)'!D63 -> 32 | E10: =+'TablasInformes (1)'!E63 -> 35
C16: Periodo Actual | D16: T+1 | E16: T+2
A17: Producto Interior Bruto | B17: España | C17: =+'TablasInformes (1)'!C64 -> 27 | D17: =+'TablasInformes (1)'!D64 -> 23 | E17: =+'TablasInformes (1)'!E64 -> 21
B18: Portugal | C18: =+'TablasInformes (1)'!C65 -> 27 | D18: =+'TablasInformes (1)'!D65 -> 22 | E18: =+'TablasInformes (1)'!E65 -> 18
B19: Francia | C19: =+'TablasInformes (1)'!C66 -> 22 | D19: =+'TablasInformes (1)'!D66 -> 16 | E19: =+'TablasInformes (1)'!E66 -> 21
B20: Italia | C20: =+'TablasInformes (1)'!C67 -> 24 | D20: =+'TablasInformes (1)'!D67 -> 19 | E20: =+'TablasInformes (1)'!E67 -> 23
B21: Centro Europa | C21: =+'TablasInformes (1)'!C68 -> 9 | D21: =+'TablasInformes (1)'!D68 -> 15 | E21: =+'TablasInformes (1)'!E68 -> 22
B22: Polonia | C22: =+'TablasInformes (1)'!C69 -> 31 | D22: =+'TablasInformes (1)'!D69 -> 23 | E22: =+'TablasInformes (1)'!E69 -> 18
B23: Mexico | C23: =+'TablasInformes (1)'!C70 -> 28 | D23: =+'TablasInformes (1)'!D70 -> 21 | E23: =+'TablasInformes (1)'!E70 -> 23
C32: Periodo Actual | D32: T+1 | E32: T+2
A33: Tipo de Interes | B33: España | C33: =+'TablasInformes (1)'!C71 -> 24 | D33: =+'TablasInformes (1)'!D71 -> 0 | E33: =+'TablasInformes (1)'!E71 -> 0
B34: Marruecos | C34: =+'TablasInformes (1)'!C72 -> 36 | D34: =+'TablasInformes (1)'!D72 -> 0 | E34: =+'TablasInformes (1)'!E72 -> 0
B35: Mexico | C35: =+'TablasInformes (1)'!C73 -> 52 | D35: =+'TablasInformes (1)'!D73 -> 0 | E35: =+'TablasInformes (1)'!E73 -> 0
B36: China | C36: =+'TablasInformes (1)'!C74 -> 55 | D36: =+'TablasInformes (1)'!D74 -> 0 | E36: =+'TablasInformes (1)'!E74 -> 0

Sheet 5
A1: 5
A2: Indicadores Clave de la Compania Drink2Go
B3: Ano 0 | C3: Ano -1 | D3: Diferencia | E3: Variacion
A4: Unidades Vendidas | B4: =+'TablasInformes (1)'!C79 -> 10555331 | C4: =+'TablasInformes (1)'!D79 -> 10146898 | D4: =+'TablasInformes (1)'!E79 -> 408433 | E4: =+'TablasInformes (1)'!F79 -> 0.4
A5: Participacion de Mercado | B5: =+'TablasInformes (1)'!C80 -> 1.68 | C5: =+'TablasInformes (1)'!D80 -> 1.65 | D5: =+'TablasInformes (1)'!E80 -> 0 | E5: =+'TablasInformes (1)'!F80 -> 0.18
A6: Ingresos | B6: =+'TablasInformes (1)'!C81 -> 21517990 | C6: =+'TablasInformes (1)'!D81 -> 19829118 | D6: =+'TablasInformes (1)'!E81 -> 1688872 | E6: =+'TablasInformes (1)'!F81 -> 0.85
A7: Resultado Bruto | B7: =+'TablasInformes (1)'!C82 -> -188802 | C7: =+'TablasInformes (1)'!D82 -> 2403283 | D7: =+'TablasInformes (1)'!E82 -> -2592084 | E7: =+'TablasInformes (1)'!F82 -> -10.79
A8: Ratio Resultado Bruto sobre Ingresos- | B8: =+'TablasInformes (1)'!C83 -> -0.09 | C8: =+'TablasInformes (1)'!D83 -> 1.21 | D8: =+'TablasInformes (1)'!E83 -> -130 | E8: =+'TablasInformes (1)'!F83 -> -10.73
A9: Resultado Neto | B9: =+'TablasInformes (1)'!C84 -> -1479023 | C9: =+'TablasInformes (1)'!D84 -> 1244268 | D9: =+'TablasInformes (1)'!E84 -> -2723291 | E9: =+'TablasInformes (1)'!F84 -> -21.89
A10: Rentabilidad sobre Patrimonio Neto - | B10: =+'TablasInformes (1)'!C85 -> -0.78 | C10: =+'TablasInformes (1)'!D85 -> 0.45 | D10: =+'TablasInformes (1)'!E85 -> -123 | E10: =+'TablasInformes (1)'!F85 -> -27.35
A11: Rendimiento del Activo | B11: =+'TablasInformes (1)'!C86 -> -0.07 | C11: =+'TablasInformes (1)'!D86 -> 0.83 | D11: =+'TablasInformes (1)'!E86 -> -89 | E11: =+'TablasInformes (1)'!F86 -> -10.79
A12: Total Pasivo sobre Patrimonio | B12: =+'TablasInformes (1)'!C87 -> 0.05 | C12: =+'TablasInformes (1)'!D87 -> 0.04 | D12: =+'TablasInformes (1)'!E87 -> 1 | E12: =+'TablasInformes (1)'!F87 -> 3.25
A13: Capacidad Fabricacion Total - Litro o Kilo | B13: =+'TablasInformes (1)'!C88 -> 10785200 | C13: =+'TablasInformes (1)'!D88 -> 10511000 | D13: =+'TablasInformes (1)'!E88 -> 274200 | E13: =+'TablasInformes (1)'!F88 -> 0.26
A14: Tasa Ocupacion Fabricas - | B14: =+'TablasInformes (1)'!C89 -> 9.9 | C14: =+'TablasInformes (1)'!D89 -> 9.77 | D14: =+'TablasInformes (1)'!E89 -> 13 | E14: =+'TablasInformes (1)'!F89 -> 0.13
A15: Unidades Inventario sobre Ventas - | B15: =+'TablasInformes (1)'!C90 -> 1.2 | C15: =+'TablasInformes (1)'!D90 -> 1.11 | D15: =+'TablasInformes (1)'!E90 -> 8 | E15: =+'TablasInformes (1)'!F90 -> 0.76
... A19: Cobertura Distribucion - escala 1 a 100- | B19: =+'TablasInformes (1)'!C94 -> 4.11 | C19: =+'TablasInformes (1)'!D94 -> 4.12 | D19: =+'TablasInformes (1)'!E94 -> 0 | E19: =+'TablasInformes (1)'!F94 -> -0.02

Sheet 6
A1: 6
A2: Indicadores Clave de la Compania.
B3: GlobalBiz | C3: FreshMarket | D3: SparklingCo | E3: QualityMax | F3: Drink2Go
A4: Unidades Vendidas | B4: =+'TablasInformes (1)'!B99 -> 13710419 | C4: =+'TablasInformes (1)'!C99 -> 14426726 | D4: =+'TablasInformes (1)'!D99 -> 13502462 | E4: =+'TablasInformes (1)'!E99 -> 10643463 | F4: =+'TablasInformes (1)'!F99 -> 10555331
A5: Cuota de Mercado | B5: =+'TablasInformes (1)'!B100 -> 2.18 | C5: =+'TablasInformes (1)'!C100 -> 2.3 | D5: =+'TablasInformes (1)'!D100 -> 2.15 | E5: =+'TablasInformes (1)'!E100 -> 1.69 | F5: =+'TablasInformes (1)'!F100 -> 1.68
A6: Ingresos | B6: =+'TablasInformes (1)'!B101 -> 27027948 | C6: =+'TablasInformes (1)'!C101 -> 23052926 | D6: =+'TablasInformes (1)'!D101 -> 20193200 | E6: =+'TablasInformes (1)'!E101 -> 20913542 | F6: =+'TablasInformes (1)'!F101 -> 21517990
A7: Resultado Bruto | B7: =+'TablasInformes (1)'!B102 -> 8648527 | C7: =+'TablasInformes (1)'!C102 -> 6561048 | D7: =+'TablasInformes (1)'!D102 -> 5140601 | E7: =+'TablasInformes (1)'!E102 -> 7171972 | F7: =+'TablasInformes (1)'!F102 -> -188802
A8: Ratio Beneficio Bruto sobre Ingresos- | B8: =+'TablasInformes (1)'!B103 -> 3.2 | C8: =+'TablasInformes (1)'!C103 -> 2.85 | D8: =+'TablasInformes (1)'!D103 -> 2.55 | E8: =+'TablasInformes (1)'!E103 -> 3.43 | F8: =+'TablasInformes (1)'!F103 -> -0.09
A9: Resultado Neto | B9: =+'TablasInformes (1)'!B104 -> 6991802 | C9: =+'TablasInformes (1)'!C104 -> 4827083 | D9: =+'TablasInformes (1)'!D104 -> 3309868 | E9: =+'TablasInformes (1)'!E104 -> 6033841 | F9: =+'TablasInformes (1)'!F104 -> -1479023
A10: Rentabilidad sobre Patrimonio Neto - | B10: =+'TablasInformes (1)'!B105 -> 1.7 | C10: =+'TablasInformes (1)'!C105 -> 1.19 | D10: =+'TablasInformes (1)'!D105 -> 1.26 | E10: =+'TablasInformes (1)'!E105 -> 1.49 | F10: =+'TablasInformes (1)'!F105 -> -0.78
A11: Rendimiento del Activo | B11: =+'TablasInformes (1)'!B106 -> 1.91 | C11: =+'TablasInformes (1)'!C106 -> 1.46 | D11: =+'TablasInformes (1)'!D106 -> 1.43 | E11: =+'TablasInformes (1)'!E106 -> 1.87 | F11: =+'TablasInformes (1)'!F106 -> -0.07
A12: Total Pasivo sobre Patrimonio | B12: =+'TablasInformes (1)'!B107 -> 5 | C12: =+'TablasInformes (1)'!C107 -> 5 | D12: =+'TablasInformes (1)'!D107 -> 8 | E12: =+'TablasInformes (1)'!E107 -> 3 | F12: =+'TablasInformes (1)'!F107 -> 5
A13: Capacidad Fabricacion Total | B13: =+'TablasInformes (1)'!B108 -> 13481500 | C13: =+'TablasInformes (1)'!C108 -> 16177800 | D13: =+'TablasInformes (1)'!D108 -> 13481500 | E13: =+'TablasInformes (1)'!E108 -> 10785200 | F13: =+'TablasInformes (1)'!F108 -> 10785200
A14: Tasa Ocupacion Fabricas - | B14: =+'TablasInformes (1)'!B109 -> 10 | C14: =+'TablasInformes (1)'!C109 -> 8.97 | D14: =+'TablasInformes (1)'!D109 -> 10 | E14: =+'TablasInformes (1)'!E109 -> 9.91 | F14: =+'TablasInformes (1)'!F109 -> 9.9
A15: Unidades Inventario sobre Ventas - | B15: 0.071 | C15: 0.08 | D15: 0.071 | E15: 0.079 | F15: 0.12 | G15: =B15/10 -> 0.0071 | H15: =C15/10 -> 0.008 | I15: =D15/10 -> 0.0071 | J15: =E15/10 -> 0.0079 | K15: =F15/10 -> 0.012
A16: Valor de Marca - escala 1 a 100- | B16: =+'TablasInformes (1)'!B111 -> 40 | C16: =+'TablasInformes (1)'!C111 -> 49 | D16: =+'TablasInformes (1)'!D111 -> 28 | E16: =+'TablasInformes (1)'!E111 -> 28 | F16: =+'TablasInformes (1)'!F111 -> 49
A17: Valor de Producto - escala 1 a 10- | B17: =+'TablasInformes (1)'!B112 -> 81 | C17: =+'TablasInformes (1)'!C112 -> 79 | D17: =+'TablasInformes (1)'!D112 -> 78 | E17: =+'TablasInformes (1)'!E112 -> 79 | F17: =+'TablasInformes (1)'!F112 -> 79
A18: Tecnologia Industrial - escala 1 a 10- | B18: =+'TablasInformes (1)'!B113 -> 9 | C18: =+'TablasInformes (1)'!C113 -> 9 | D18: =+'TablasInformes (1)'!D113 -> 9 | E18: =+'TablasInformes (1)'!E113 -> 9 | F18: =+'TablasInformes (1)'!F113 -> 9
A19: Cobertura Distribucion - escala 1 a 100- | B19: =+'TablasInformes (1)'!B114 -> 2.59 | C19: =+'TablasInformes (1)'!C114 -> 3.17 | D19: =+'TablasInformes (1)'!D114 -> 3.78 | E19: =+'TablasInformes (1)'!E114 -> 1.92 | F19: =+'TablasInformes (1)'!F114 -> 4.11

Sheet 7
A1: 7
A2: Indicadores Clave de la Compania Drink2Go
B3: =+'TablasInformes (1)'!B118 -> 2023 | C3: =+'TablasInformes (1)'!C118 -> 2024 | D3: =+'TablasInformes (1)'!D118 -> 2025 | E3: =+'TablasInformes (1)'!E118 -> 2026 | F3: =+'TablasInformes (1)'!F118 -> 2027 | G3: =+'TablasInformes (1)'!G118 -> 2028
A4: Unidades Vendidas | B4: =+'TablasInformes (1)'!B120 -> 6641121 | C4: =+'TablasInformes (1)'!C120 -> 6841045 | D4: =+'TablasInformes (1)'!D120 -> 8078565 | E4: =+'TablasInformes (1)'!E120 -> 8686200 | F4: =+'TablasInformes (1)'!F120 -> 10146898 | G4: =+'TablasInformes (1)'!G120 -> 10555331 | J4: mercado y finanzas
A5: Participacion de Mercado | B5: =+'TablasInformes (1)'!B121 -> 0.2 | C5: =+'TablasInformes (1)'!C121 -> 0.187 | D5: =+'TablasInformes (1)'!D121 -> 0.17 | E5: =+'TablasInformes (1)'!E121 -> 0.155 | F5: =+'TablasInformes (1)'!F121 -> 0.165 | G5: =+'TablasInformes (1)'!G121 -> 0.168
A6: Ingresos | B6: =+'TablasInformes (1)'!B122 -> 7976033 | C6: =+'TablasInformes (1)'!C122 -> 10787901 | D6: =+'TablasInformes (1)'!D122 -> 16607629 | E6: =+'TablasInformes (1)'!E122 -> 19958018 | F6: =+'TablasInformes (1)'!F122 -> 19829118 | G6: =+'TablasInformes (1)'!G122 -> 21517990
A7: Resultado Bruto | B7: =+'TablasInformes (1)'!B123 -> 847700 | C7: =+'TablasInformes (1)'!C123 -> 3100303 | D7: =+'TablasInformes (1)'!D123 -> 3422755 | E7: =+'TablasInformes (1)'!E123 -> 4903309 | F7: =+'TablasInformes (1)'!F123 -> 2403283 | G7: =+'TablasInformes (1)'!G123 -> -188802
A8: Ratio Beneficio Bruto sobre Ingresos- | B8: =+'TablasInformes (1)'!B124 -> 1.06 | C8: =+'TablasInformes (1)'!C124 -> 2.87 | D8: =+'TablasInformes (1)'!D124 -> 2.06 | E8: =+'TablasInformes (1)'!E124 -> 2.46 | F8: =+'TablasInformes (1)'!F124 -> 1.21 | G8: =+'TablasInformes (1)'!G124 -> -0.09 | J8: naranja | K8: financiera
A9: Resultado Neto | B9: =+'TablasInformes (1)'!B125 -> 184751 | C9: =+'TablasInformes (1)'!C125 -> 2217466 | D9: =+'TablasInformes (1)'!D125 -> 2182566 | E9: =+'TablasInformes (1)'!E125 -> 3699908 | F9: =+'TablasInformes (1)'!F125 -> 1244268 | G9: =+'TablasInformes (1)'!G125 -> -1479023 | J9: rojo | K9: mercado
A10: Rentabilidad sobre Patrimonio Neto - | B10: =+'TablasInformes (1)'!B126 -> 0.01 | C10: =+'TablasInformes (1)'!C126 -> 0.1 | D10: =+'TablasInformes (1)'!D126 -> 0.095 | E10: =+'TablasInformes (1)'!E126 -> 0.136 | F10: =+'TablasInformes (1)'!F126 -> 0.045 | G10: =+'TablasInformes (1)'!G126 -> -0.078 | J10: verde | K10: produccioon
A11: Rendimiento del Activo | B11: =+'TablasInformes (1)'!B127 -> 0.045 | C11: =+'TablasInformes (1)'!C127 -> 0.126 | D11: =+'TablasInformes (1)'!D127 -> 0.119 | E11: =+'TablasInformes (1)'!E127 -> 0.162 | F11: =+'TablasInformes (1)'!F127 -> 0.083 | G11: =+'TablasInformes (1)'!G127 -> -0.007
A12: Total Pasivo sobre Patrimonio | B12: =+'TablasInformes (1)'!B128 -> 3 | C12: =+'TablasInformes (1)'!C128 -> 5 | D12: =+'TablasInformes (1)'!D128 -> 7 | E12: =+'TablasInformes (1)'!E128 -> 5 | F12: =+'TablasInformes (1)'!F128 -> 4 | G12: =+'TablasInformes (1)'!G128 -> 5
A13: Capacidad Fabricacion Total | B13: =+'TablasInformes (1)'!B129 -> 7334850 | C13: =+'TablasInformes (1)'!C129 -> 7471950 | D13: =+'TablasInformes (1)'!D129 -> 10145400 | E13: =+'TablasInformes (1)'!E129 -> 10328200 | F13: =+'TablasInformes (1)'!F129 -> 10511000 | G13: =+'TablasInformes (1)'!G129 -> 10785200 | I13: =(G13-B13)/B13 -> 0.47040498
A14: Tasa Ocupacion Fabricas - | B14: =+'TablasInformes (1)'!B130 -> 0.887 | C14: =+'TablasInformes (1)'!C130 -> 0.963 | D14: =+'TablasInformes (1)'!D130 -> 0.821 | E14: =+'TablasInformes (1)'!E130 -> 0.866 | F14: =+'TablasInformes (1)'!F130 -> 0.977 | G14: =+'TablasInformes (1)'!G130 -> 0.99
A15: Unidades Inventario sobre Ventas - | B15: =+'TablasInformes (1)'!B131 -> 0.022 | C15: =+'TablasInformes (1)'!C131 -> 0.073 | D15: =+'TablasInformes (1)'!D131 -> 0.093 | E15: =+'TablasInformes (1)'!E131 -> 0.116 | F15: =+'TablasInformes (1)'!F131 -> 0.111 | G15: =+'TablasInformes (1)'!G131 -> 0.12
A16: Valor de Marca - escala 1 a 100- | B16: =+'TablasInformes (1)'!B132 -> 35 | C16: =+'TablasInformes (1)'!C132 -> 28 | D16: =+'TablasInformes (1)'!D132 -> 49 | E16: =+'TablasInformes (1)'!E132 -> 36 | F16: =+'TablasInformes (1)'!F132 -> 30 | G16: =+'TablasInformes (1)'!G132 -> 49
A17: Valor de Producto - escala 1 a 10- | B17: =+'TablasInformes (1)'!B133 -> 7.4 | C17: =+'TablasInformes (1)'!C133 -> 7.4 | D17: =+'TablasInformes (1)'!D133 -> 7.6 | E17: =+'TablasInformes (1)'!E133 -> 7.8 | F17: =+'TablasInformes (1)'!F133 -> 7.9 | G17: =+'TablasInformes (1)'!G133 -> 7.9
A18: Tecnologia Industrial - escala 1 a 10- | B18: =+'TablasInformes (1)'!B134 -> 4 | C18: =+'TablasInformes (1)'!C134 -> 5 | D18: =+'TablasInformes (1)'!D134 -> 6 | E18: =+'TablasInformes (1)'!E134 -> 7 | F18: =+'TablasInformes (1)'!F134 -> 8 | G18: =+'TablasInformes (1)'!G134 -> 9
A19: º | B19: =+'TablasInformes (1)'!B135 -> 0.439 | C19: =+'TablasInformes (1)'!C135 -> 0.408 | D19: =+'TablasInformes (1)'!D135 -> 0.397 | E19: =+'TablasInformes (1)'!E135 -> 0.409 | F19: =+'TablasInformes (1)'!F135 -> 0.412 | G19: =+'TablasInformes (1)'!G135 -> 0.411
B21: =B15/10 -> 0.0022 | C21: =C15/10 -> 0.0073 | D21: =D15/10 -> 0.0093 | E21: =E15/10 -> 0.0116 | F21: =F15/10 -> 0.0111 | G21: =G15/10 -> 0.012
B70: 2023 | C70: 2024 | D70: 2025 | E70: 2026 | F70: 2027 | G70: 2028
A71: Unidades Vendidas | B71: 6641121 | C71: 6841045 | D71: 8078565 | E71: 8686200 | F71: 10146898 | G71: 10555331
A72: Porcentaje de Crecimiento | C72: =(C71-B71)/C71 -> 0.02922419 | D72: =(D71-C71)/D71 -> 0.15318562 | E72: =(E71-D71)/E71 -> 0.069954065 | F72: =(F71-E71)/F71 -> 0.14395513 | G72: =(G71-F71)/G71 -> 0.038694476
A75: Valor de Marca - escala 1 a 100- | B75: 35 | C75: 28 | D75: 49 | E75: 36 | F75: 30 | G75: 49
C76: =(C75-B75)/C75 -> -0.25 | D76: =(D75-C75)/D75 -> 0.42857143 | E76: =(E75-D75)/E75 -> -0.36111111 | F76: =(F75-E75)/F75 -> -0.2 | G76: =(G75-B75)/G75 -> 0.28571429

Sheet 8
A1: 8
A2: Nivel de precios por compania Drink2Go
C3: =+'TablasInformes (1)'!C139 -> 2023 | D3: =+'TablasInformes (1)'!D139 -> 2024 | E3: =+'TablasInformes (1)'!E139 -> 2025 | F3: =+'TablasInformes (1)'!F139 -> 2026 | G3: =+'TablasInformes (1)'!G139 -> 2027 | H3: =+'TablasInformes (1)'!H139 -> 2028
A4: Espana | B4: Refrescos | C4: =+'TablasInformes (1)'!C141 -> 12 | D4: =+'TablasInformes (1)'!D141 -> 16 | E4: =+'TablasInformes (1)'!E141 -> 20 | F4: =+'TablasInformes (1)'!F141 -> 20 | G4: =+'TablasInformes (1)'!G141 -> 20 | H4: =+'TablasInformes (1)'!H141 -> 25
B5: Isotonicas | C5: =+'TablasInformes (1)'!C142 -> 18 | D5: =+'TablasInformes (1)'!D142 -> 24 | E5: =+'TablasInformes (1)'!E142 -> 28 | F5: =+'TablasInformes (1)'!F142 -> 28 | G5: =+'TablasInformes (1)'!G142 -> 28 | H5: =+'TablasInformes (1)'!H142 -> 28
B6: Zumos | C6: =+'TablasInformes (1)'!C143 -> 22 | D6: =+'TablasInformes (1)'!D143 -> 30 | E6: =+'TablasInformes (1)'!E143 -> 35 | F6: =+'TablasInformes (1)'!F143 -> 35 | G6: =+'TablasInformes (1)'!G143 -> 30 | H6: =+'TablasInformes (1)'!H143 -> 29
A7: Portugal | B7: Refrescos | C7: =+'TablasInformes (1)'!C144 -> 11 | D7: =+'TablasInformes (1)'!D144 -> 16 | E7: =+'TablasInformes (1)'!E144 -> 20 | F7: =+'TablasInformes (1)'!F144 -> 20 | G7: =+'TablasInformes (1)'!G144 -> 20 | H7: =+'TablasInformes (1)'!H144 -> 24
B8: Isotonicas | C8: =+'TablasInformes (1)'!C145 -> 17 | D8: =+'TablasInformes (1)'!D145 -> 23 | E8: =+'TablasInformes (1)'!E145 -> 28 | F8: =+'TablasInformes (1)'!F145 -> 28 | G8: =+'TablasInformes (1)'!G145 -> 28 | H8: =+'TablasInformes (1)'!H145 -> 28
B9: Zumos | C9: =+'TablasInformes (1)'!C146 -> 23 | D9: =+'TablasInformes (1)'!D146 -> 31 | E9: =+'TablasInformes (1)'!E146 -> 36 | F9: =+'TablasInformes (1)'!F146 -> 36 | G9: =+'TablasInformes (1)'!G146 -> 3 | H9: =+'TablasInformes (1)'!H146 -> 29
A10: Francia | B10: Refrescos | C10: =+'TablasInformes (1)'!C147 -> 13 | D10: =+'TablasInformes (1)'!D147 -> 18 | E10: =+'TablasInformes (1)'!E147 -> 25 | F10: =+'TablasInformes (1)'!F147 -> 25 | G10: =+'TablasInformes (1)'!G147 -> 23 | H10: =+'TablasInformes (1)'!H147 -> 27
B11: Isotonicas | C11: =+'TablasInformes (1)'!C148 -> 19 | D11: =+'TablasInformes (1)'!D148 -> 26 | E11: =+'TablasInformes (1)'!E148 -> 30 | F11: =+'TablasInformes (1)'!F148 -> 30 | G11: =+'TablasInformes (1)'!G148 -> 28 | H11: =+'TablasInformes (1)'!H148 -> 28
B12: Zumos | C12: =+'TablasInformes (1)'!C149 -> 25 | D12: =+'TablasInformes (1)'!D149 -> 34 | E12: =+'TablasInformes (1)'!E149 -> 38 | F12: =+'TablasInformes (1)'!F149 -> 38 | G12: =+'TablasInformes (1)'!G149 -> 32 | H12: =+'TablasInformes (1)'!H149 -> 3
A13: Italia | B13: Refrescos | C13: =+'TablasInformes (1)'!C150 -> 0 | D13: =+'TablasInformes (1)'!D150 -> 16 | E13: =+'TablasInformes (1)'!E150 -> 24 | F13: =+'TablasInformes (1)'!F150 -> 3 | G13: =+'TablasInformes (1)'!G150 -> 24 | H13: =+'TablasInformes (1)'!H150 -> 28
B14: Isotonicas | C14: =+'TablasInformes (1)'!C151 -> 0 | D14: =+'TablasInformes (1)'!D151 -> 24 | E14: =+'TablasInformes (1)'!E151 -> 36 | F14: =+'TablasInformes (1)'!F151 -> 40 | G14: =+'TablasInformes (1)'!G151 -> 30 | H14: =+'TablasInformes (1)'!H151 -> 31
B15: Zumos | C15: =+'TablasInformes (1)'!C152 -> 0 | D15: =+'TablasInformes (1)'!D152 -> 30 | E15: =+'TablasInformes (1)'!E152 -> 45 | F15: =+'TablasInformes (1)'!F152 -> 56 | G15: =+'TablasInformes (1)'!G152 -> 34 | H15: =+'TablasInformes (1)'!H152 -> 34
A16: Centro Europa | B16: Refrescos | C16: =+'TablasInformes (1)'!C153 -> 0 | D16: =+'TablasInformes (1)'!D153 -> 0 | E16: =+'TablasInformes (1)'!E153 -> 0 | F16: =+'TablasInformes (1)'!F153 -> 0 | G16: =+'TablasInformes (1)'!G153 -> 28 | H16: =+'TablasInformes (1)'!H153 -> 28
B17: Isotonicas | C17: =+'TablasInformes (1)'!C154 -> 0 | D17: =+'TablasInformes (1)'!D154 -> 0 | E17: =+'TablasInformes (1)'!E154 -> 0 | F17: =+'TablasInformes (1)'!F154 -> 0 | G17: =+'TablasInformes (1)'!G154 -> 34 | H17: =+'TablasInformes (1)'!H154 -> 32
B18: Zumos | C18: =+'TablasInformes (1)'!C155 -> 0 | D18: =+'TablasInformes (1)'!D155 -> 0 | E18: =+'TablasInformes (1)'!E155 -> 0 | F18: =+'TablasInformes (1)'!F155 -> 0 | G18: =+'TablasInformes (1)'!G155 -> 35 | H18: =+'TablasInformes (1)'!H155 -> 32
A19: Polonia | B19: Refrescos | C19: =+'TablasInformes (1)'!C156 -> 0 | D19: =+'TablasInformes (1)'!D156 -> 0 | E19: =+'TablasInformes (1)'!E156 -> 0 | F19: =+'TablasInformes (1)'!F156 -> 24 | G19: =+'TablasInformes (1)'!G156 -> 26 | H19: =+'TablasInformes (1)'!H156 -> 27
B20: Isotonicas | C20: =+'TablasInformes (1)'!C157 -> 0 | D20: =+'TablasInformes (1)'!D157 -> 0 | E20: =+'TablasInformes (1)'!E157 -> 0 | F20: =+'TablasInformes (1)'!F157 -> 28 | G20: =+'TablasInformes (1)'!G157 -> 32 | H20: =+'TablasInformes (1)'!H157 -> 32
B21: Zumos | C21: =+'TablasInformes (1)'!C158 -> 0 | D21: =+'TablasInformes (1)'!D158 -> 0 | E21: =+'TablasInformes (1)'!E158 -> 0 | F21: =+'TablasInformes (1)'!F158 -> 35 | G21: =+'TablasInformes (1)'!G158 -> 38 | H21: =+'TablasInformes (1)'!H158 -> 35
A22: Mexico | B22: Refrescos | C22: =+'TablasInformes (1)'!C159 -> 0 | D22: =+'TablasInformes (1)'!D159 -> 0 | E22: =+'TablasInformes (1)'!E159 -> 24 | F22: =+'TablasInformes (1)'!F159 -> 3 | G22: =+'TablasInformes (1)'!G159 -> 3 | H22: =+'TablasInformes (1)'!H159 -> 32
B23: Isotonicas | C23: =+'TablasInformes (1)'!C160 -> 0 | D23: =+'TablasInformes (1)'!D160 -> 0 | E23: =+'TablasInformes (1)'!E160 -> 36 | F23: =+'TablasInformes (1)'!F160 -> 4 | G23: =+'TablasInformes (1)'!G160 -> 29 | H23: =+'TablasInformes (1)'!H160 -> 33
B24: Zumos | C24: =+'TablasInformes (1)'!C161 -> 0 | D24: =+'TablasInformes (1)'!D161 -> 0 | E24: =+'TablasInformes (1)'!E161 -> 45 | F24: =+'TablasInformes (1)'!F161 -> 5 | G24: =+'TablasInformes (1)'!G161 -> 5 | H24: =+'TablasInformes (1)'!H161 -> 38

Sheet 9
A1: 9
A2: Nivel de precios por compania.
C3: GlobalBiz | D3: FreshMarket | E3: SparklingCo | F3: QualityMax | G3: Drink2Go
A4: Espana | B4: Refrescos | C4: =+'TablasInformes (1)'!C166 -> 19 | D4: =+'TablasInformes (1)'!D166 -> 17 | E4: =+'TablasInformes (1)'!E166 -> 17 | F4: =+'TablasInformes (1)'!F166 -> 20 | G4: =+'TablasInformes (1)'!G166 -> 25
B5: Isotonicas | C5: =+'TablasInformes (1)'!C167 -> 28 | D5: =+'TablasInformes (1)'!D167 -> 26 | E5: =+'TablasInformes (1)'!E167 -> 24 | F5: =+'TablasInformes (1)'!F167 -> 27 | G5: =+'TablasInformes (1)'!G167 -> 28
B6: Zumos | C6: =+'TablasInformes (1)'!C168 -> 31 | D6: =+'TablasInformes (1)'!D168 -> 3 | E6: =+'TablasInformes (1)'!E168 -> 27 | F6: =+'TablasInformes (1)'!F168 -> 32 | G6: =+'TablasInformes (1)'!G168 -> 29
A7: Portugal | B7: Refrescos | C7: =+'TablasInformes (1)'!C169 -> 19 | D7: =+'TablasInformes (1)'!D169 -> 17 | E7: =+'TablasInformes (1)'!E169 -> 17 | F7: =+'TablasInformes (1)'!F169 -> 19 | G7: =+'TablasInformes (1)'!G169 -> 24
B8: Isotonicas | C8: =+'TablasInformes (1)'!C170 -> 26 | D8: =+'TablasInformes (1)'!D170 -> 25 | E8: =+'TablasInformes (1)'!E170 -> 23 | F8: =+'TablasInformes (1)'!F170 -> 27 | G8: =+'TablasInformes (1)'!G170 -> 28
B9: Zumos | C9: =+'TablasInformes (1)'!C171 -> 31 | D9: =+'TablasInformes (1)'!D171 -> 3 | E9: =+'TablasInformes (1)'!E171 -> 27 | F9: =+'TablasInformes (1)'!F171 -> 34 | G9: =+'TablasInformes (1)'!G171 -> 29
A10: Francia | B10: Refrescos | C10: =+'TablasInformes (1)'!C172 -> 20 | D10: =+'TablasInformes (1)'!D172 -> 20 | E10: =+'TablasInformes (1)'!E172 -> 18 | F10: =+'TablasInformes (1)'!F172 -> 21 | G10: =+'TablasInformes (1)'!G172 -> 27
B11: Isotonicas | C11: =+'TablasInformes (1)'!C173 -> 28 | D11: =+'TablasInformes (1)'!D173 -> 29 | E11: =+'TablasInformes (1)'!E173 -> 27 | F11: =+'TablasInformes (1)'!F173 -> 28 | G11: =+'TablasInformes (1)'!G173 -> 28
B12: Zumos | C12: =+'TablasInformes (1)'!C174 -> 32 | D12: =+'TablasInformes (1)'!D174 -> 35 | E12: =+'TablasInformes (1)'!E174 -> 32 | F12: =+'TablasInformes (1)'!F174 -> 33 | G12: =+'TablasInformes (1)'!G174 -> 3
A13: Italia | B13: Refrescos | C13: =+'TablasInformes (1)'!C175 -> 22 | D13: =+'TablasInformes (1)'!D175 -> 17 | E13: =+'TablasInformes (1)'!E175 -> 17 | F13: =+'TablasInformes (1)'!F175 -> 22 | G13: =+'TablasInformes (1)'!G175 -> 28
B14: Isotonicas | C14: =+'TablasInformes (1)'!C176 -> 29 | D14: =+'TablasInformes (1)'!D176 -> 26 | E14: =+'TablasInformes (1)'!E176 -> 24 | F14: =+'TablasInformes (1)'!F176 -> 27 | G14: =+'TablasInformes (1)'!G176 -> 31
B15: Zumos | C15: =+'TablasInformes (1)'!C177 -> 36 | D15: =+'TablasInformes (1)'!D177 -> 3 | E15: =+'TablasInformes (1)'!E177 -> 27 | F15: =+'TablasInformes (1)'!F177 -> 32 | G15: =+'TablasInformes (1)'!G177 -> 34
A16: Centro Europa | B16: Refrescos | C16: =+'TablasInformes (1)'!C178 -> 23 | D16: =+'TablasInformes (1)'!D178 -> 17 | E16: =+'TablasInformes (1)'!E178 -> 16 | F16: =+'TablasInformes (1)'!F178 -> 25 | G16: =+'TablasInformes (1)'!G178 -> 28
B17: Isotonicas | C17: =+'TablasInformes (1)'!C179 -> 3 | D17: =+'TablasInformes (1)'!D179 -> 26 | E17: =+'TablasInformes (1)'!E179 -> 24 | F17: =+'TablasInformes (1)'!F179 -> 30 | G17: =+'TablasInformes (1)'!G179 -> 32
B18: Zumos | C18: =+'TablasInformes (1)'!C180 -> 35 | D18: =+'TablasInformes (1)'!D180 -> 3 | E18: =+'TablasInformes (1)'!E180 -> 27 | F18: =+'TablasInformes (1)'!F180 -> 35 | G18: =+'TablasInformes (1)'!G180 -> 32
A19: Polonia | B19: Refrescos | C19: =+'TablasInformes (1)'!C181 -> 22 | D19: =+'TablasInformes (1)'!D181 -> 18 | E19: =+'TablasInformes (1)'!E181 -> 16 | F19: =+'TablasInformes (1)'!F181 -> 25 | G19: =+'TablasInformes (1)'!G181 -> 27
B20: Isotonicas | C20: =+'TablasInformes (1)'!C182 -> 31 | D20: =+'TablasInformes (1)'!D182 -> 27 | E20: =+'TablasInformes (1)'!E182 -> 25 | F20: =+'TablasInformes (1)'!F182 -> 30 | G20: =+'TablasInformes (1)'!G182 -> 32
B21: Zumos | C21: =+'TablasInformes (1)'!C183 -> 36 | D21: =+'TablasInformes (1)'!D183 -> 33 | E21: =+'TablasInformes (1)'!E183 -> 3 | F21: =+'TablasInformes (1)'!F183 -> 35 | G21: =+'TablasInformes (1)'!G183 -> 35
A22: Mexico | B22: Refrescos | C22: =+'TablasInformes (1)'!C184 -> 23 | D22: =+'TablasInformes (1)'!D184 -> 17 | E22: =+'TablasInformes (1)'!E184 -> 16 | F22: =+'TablasInformes (1)'!F184 -> 23 | G22: =+'TablasInformes (1)'!G184 -> 32
B23: Isotonicas | C23: =+'TablasInformes (1)'!C185 -> 31 | D23: =+'TablasInformes (1)'!D185 -> 26 | E23: =+'TablasInformes (1)'!E185 -> 24 | F23: =+'TablasInformes (1)'!F185 -> 28 | G23: =+'TablasInformes (1)'!G185 -> 33
B24: Zumos | C24: =+'TablasInformes (1)'!C186 -> 36 | D24: =+'TablasInformes (1)'!D186 -> 30 | E24: =+'TablasInformes (1)'!E186 -> 27 | F24: =+'TablasInformes (1)'!F186 -> 33 | G24: =+'TablasInformes (1)'!G186 -> 38

Sheet 10
A1: 10
A2: Valor de producto - Escala 1 a 10. Drink2Go
B3: =+'TablasInformes (1)'!B190 -> 2023 | C3: =+'TablasInformes (1)'!C190 -> 2024 | D3: =+'TablasInformes (1)'!D190 -> 2025 | E3: =+'TablasInformes (1)'!E190 -> 2026 | F3: =+'TablasInformes (1)'!F190 -> 2027 | G3: =+'TablasInformes (1)'!G190 -> 2028
A4: Refrescos | B4: =+'TablasInformes (1)'!B192 -> 8.3 | C4: =+'TablasInformes (1)'!C192 -> 8.3 | D4: =+'TablasInformes (1)'!D192 -> 8.3 | E4: =+'TablasInformes (1)'!E192 -> 8.3 | F4: =+'TablasInformes (1)'!F192 -> 8.3 | G4: =+'TablasInformes (1)'!G192 -> 8.3
A5: Isotonicas | B5: =+'TablasInformes (1)'!B193 -> 6.5 | C5: =+'TablasInformes (1)'!C193 -> 6.3 | D5: =+'TablasInformes (1)'!D193 -> 6.5 | E5: =+'TablasInformes (1)'!E193 -> 6.8 | F5: =+'TablasInformes (1)'!F193 -> 7.1 | G5: =+'TablasInformes (1)'!G193 -> 7.1
A6: Zumos | B6: =+'TablasInformes (1)'!B194 -> 7.4 | C6: =+'TablasInformes (1)'!C194 -> 7.7 | D6: =+'TablasInformes (1)'!D194 -> 8 | E6: =+'TablasInformes (1)'!E194 -> 8.3 | F6: =+'TablasInformes (1)'!F194 -> 8.4 | G6: =+'TablasInformes (1)'!G194 -> 8.4

Sheet 11
A1: 11
A2: Gama de producto por compania. Drink2Go | I2: TOTAL
C3: =+'TablasInformes (1)'!C198 -> 2023 | D3: =+'TablasInformes (1)'!D198 -> 2024 | E3: =+'TablasInformes (1)'!E198 -> 2025 | F3: =+'TablasInformes (1)'!F198 -> 2026 | G3: =+'TablasInformes (1)'!G198 -> 2027 | H3: =+'TablasInformes (1)'!H198 -> 2028
A4: Espana | B4: Refrescos | C4: =+'TablasInformes (1)'!C200 -> 6 | D4: =+'TablasInformes (1)'!D200 -> 8 | E4: =+'TablasInformes (1)'!E200 -> 9 | F4: =+'TablasInformes (1)'!F200 -> 10 | G4: =+'TablasInformes (1)'!G200 -> 10 | H4: =+'TablasInformes (1)'!H200 -> 11
B5: Isotonicas | C5: =+'TablasInformes (1)'!C201 -> 2 | D5: =+'TablasInformes (1)'!D201 -> 3 | E5: =+'TablasInformes (1)'!E201 -> 4 | F5: =+'TablasInformes (1)'!F201 -> 5 | G5: =+'TablasInformes (1)'!G201 -> 5 | H5: =+'TablasInformes (1)'!H201 -> 6
B6: Zumos | C6: =+'TablasInformes (1)'!C202 -> 4 | D6: =+'TablasInformes (1)'!D202 -> 5 | E6: =+'TablasInformes (1)'!E202 -> 6 | F6: =+'TablasInformes (1)'!F202 -> 7 | G6: =+'TablasInformes (1)'!G202 -> 8 | H6: =+'TablasInformes (1)'!H202 -> 8 | I6: =SUM(H4:H6) -> 25
A7: Portugal | B7: Refrescos | C7: =+'TablasInformes (1)'!C203 -> 6 | D7: =+'TablasInformes (1)'!D203 -> 8 | E7: =+'TablasInformes (1)'!E203 -> 9 | F7: =+'TablasInformes (1)'!F203 -> 10 | G7: =+'TablasInformes (1)'!G203 -> 10 | H7: =+'TablasInformes (1)'!H203 -> 11
B8: Isotonicas | C8: =+'TablasInformes (1)'!C204 -> 2 | D8: =+'TablasInformes (1)'!D204 -> 3 | E8: =+'TablasInformes (1)'!E204 -> 4 | F8: =+'TablasInformes (1)'!F204 -> 5 | G8: =+'TablasInformes (1)'!G204 -> 5 | H8: =+'TablasInformes (1)'!H204 -> 6
B9: Zumos | C9: =+'TablasInformes (1)'!C205 -> 4 | D9: =+'TablasInformes (1)'!D205 -> 5 | E9: =+'TablasInformes (1)'!E205 -> 6 | F9: =+'TablasInformes (1)'!F205 -> 7 | G9: =+'TablasInformes (1)'!G205 -> 8 | H9: =+'TablasInformes (1)'!H205 -> 8 | I9: =SUM(H7:H9) -> 25
A10: Francia | B10: Refrescos | C10: =+'TablasInformes (1)'!C206 -> 6 | D10: =+'TablasInformes (1)'!D206 -> 8 | E10: =+'TablasInformes (1)'!E206 -> 9 | F10: =+'TablasInformes (1)'!F206 -> 10 | G10: =+'TablasInformes (1)'!G206 -> 10 | H10: =+'TablasInformes (1)'!H206 -> 11
B11: Isotonicas | C11: =+'TablasInformes (1)'!C207 -> 2 | D11: =+'TablasInformes (1)'!D207 -> 3 | E11: =+'TablasInformes (1)'!E207 -> 4 | F11: =+'TablasInformes (1)'!F207 -> 5 | G11: =+'TablasInformes (1)'!G207 -> 5 | H11: =+'TablasInformes (1)'!H207 -> 6
B12: Zumos | C12: =+'TablasInformes (1)'!C208 -> 4 | D12: =+'TablasInformes (1)'!D208 -> 5 | E12: =+'TablasInformes (1)'!E208 -> 6 | F12: =+'TablasInformes (1)'!F208 -> 7 | G12: =+'TablasInformes (1)'!G208 -> 8 | H12: =+'TablasInformes (1)'!H208 -> 8 | I12: =SUM(H10:H12) -> 25
A13: Italia | B13: Refrescos | C13: =+'TablasInformes (1)'!C209 -> 0 | D13: =+'TablasInformes (1)'!D209 -> 4 | E13: =+'TablasInformes (1)'!E209 -> 8 | F13: =+'TablasInformes (1)'!F209 -> 10 | G13: =+'TablasInformes (1)'!G209 -> 10 | H13: =+'TablasInformes (1)'!H209 -> 11
B14: Isotonicas | C14: =+'TablasInformes (1)'!C210 -> 0 | D14: =+'TablasInformes (1)'!D210 -> 2 | E14: =+'TablasInformes (1)'!E210 -> 4 | F14: =+'TablasInformes (1)'!F210 -> 5 | G14: =+'TablasInformes (1)'!G210 -> 5 | H14: =+'TablasInformes (1)'!H210 -> 6
B15: Zumos | C15: =+'TablasInformes (1)'!C211 -> 0 | D15: =+'TablasInformes (1)'!D211 -> 3 | E15: =+'TablasInformes (1)'!E211 -> 6 | F15: =+'TablasInformes (1)'!F211 -> 7 | G15: =+'TablasInformes (1)'!G211 -> 8 | H15: =+'TablasInformes (1)'!H211 -> 8
A16: Centro Europa | B16: Refrescos | C16: =+'TablasInformes (1)'!C212 -> 0 | D16: =+'TablasInformes (1)'!D212 -> 0 | E16: =+'TablasInformes (1)'!E212 -> 0 | F16: =+'TablasInformes (1)'!F212 -> 0 | G16: =+'TablasInformes (1)'!G212 -> 10 | H16: =+'TablasInformes (1)'!H212 -> 11 | I16: =SUM(H14:H16) -> 25
B17: Isotonicas | C17: =+'TablasInformes (1)'!C213 -> 0 | D17: =+'TablasInformes (1)'!D213 -> 0 | E17: =+'TablasInformes (1)'!E213 -> 0 | F17: =+'TablasInformes (1)'!F213 -> 0 | G17: =+'TablasInformes (1)'!G213 -> 5 | H17: =+'TablasInformes (1)'!H213 -> 6
B18: Zumos | C18: =+'TablasInformes (1)'!C214 -> 0 | D18: =+'TablasInformes (1)'!D214 -> 0 | E18: =+'TablasInformes (1)'!E214 -> 0 | F18: =+'TablasInformes (1)'!F214 -> 0 | G18: =+'TablasInformes (1)'!G214 -> 5 | H18: =+'TablasInformes (1)'!H214 -> 8
A19: Polonia | B19: Refrescos | C19: =+'TablasInformes (1)'!C215 -> 0 | D19: =+'TablasInformes (1)'!D215 -> 0 | E19: =+'TablasInformes (1)'!E215 -> 0 | F19: =+'TablasInformes (1)'!F215 -> 2 | G19: =+'TablasInformes (1)'!G215 -> 10 | H19: =+'TablasInformes (1)'!H215 -> 11 | I19: =SUM(H17:H19) -> 25
B20: Isotonicas | C20: =+'TablasInformes (1)'!C216 -> 0 | D20: =+'TablasInformes (1)'!D216 -> 0 | E20: =+'TablasInformes (1)'!E216 -> 0 | F20: =+'TablasInformes (1)'!F216 -> 2 | G20: =+'TablasInformes (1)'!G216 -> 6 | H20: =+'TablasInformes (1)'!H216 -> 6
B21: Zumos | C21: =+'TablasInformes (1)'!C217 -> 0 | D21: =+'TablasInformes (1)'!D217 -> 0 | E21: =+'TablasInformes (1)'!E217 -> 0 | F21: =+'TablasInformes (1)'!F217 -> 2 | G21: =+'TablasInformes (1)'!G217 -> 6 | H21: =+'TablasInformes (1)'!H217 -> 8
A22: Mexico | B22: Refrescos | C22: =+'TablasInformes (1)'!C218 -> 0 | D22: =+'TablasInformes (1)'!D218 -> 0 | E22: =+'TablasInformes (1)'!E218 -> 4 | F22: =+'TablasInformes (1)'!F218 -> 5 | G22: =+'TablasInformes (1)'!G218 -> 10 | H22: =+'TablasInformes (1)'!H218 -> 11 | I22: =SUM(H20:H22) -> 25
B23: Isotonicas | C23: =+'TablasInformes (1)'!C219 -> 0 | D23: =+'TablasInformes (1)'!D219 -> 0 | E23: =+'TablasInformes (1)'!E219 -> 4 | F23: =+'TablasInformes (1)'!F219 -> 5 | G23: =+'TablasInformes (1)'!G219 -> 6 | H23: =+'TablasInformes (1)'!H219 -> 6
B24: Zumos | C24: =+'TablasInformes (1)'!C220 -> 0 | D24: =+'TablasInformes (1)'!D220 -> 0 | E24: =+'TablasInformes (1)'!E220 -> 5 | F24: =+'TablasInformes (1)'!F220 -> 6 | G24: =+'TablasInformes (1)'!G220 -> 7 | H24: =+'TablasInformes (1)'!H220 -> 8 | I24: =SUM(H22:H24) -> 25
G25: TOTAL GENERAL | I25: =SUM(I6:I24) -> 175

Sheet 12
A1: 12
A2: Gama por producto por compania.
C3: =+'TablasInformes (1)'!C223 -> 2027 | D3: =+'TablasInformes (1)'!D223 -> 2027 | E3: =+'TablasInformes (1)'!E223 -> 2027 | F3: =+'TablasInformes (1)'!F223 -> 2028 | G3: =+'TablasInformes (1)'!G223 -> 2028 | H3: =+'TablasInformes (1)'!H223 -> 2028
C4: Refrescos | D4: Isotonicas | E4: Zumos | F4: Refrescos | G4: Isotonicas | H4: Zumos
A5: GlobalBiz | B5: Espana | C5: =+'TablasInformes (1)'!C225 -> 11 | D5: =+'TablasInformes (1)'!D225 -> 6 | E5: =+'TablasInformes (1)'!E225 -> 8 | F5: =+'TablasInformes (1)'!F225 -> 12 | G5: =+'TablasInformes (1)'!G225 -> 6 | H5: =+'TablasInformes (1)'!H225 -> 8
B6: Portugal | C6: =+'TablasInformes (1)'!C226 -> 11 | D6: =+'TablasInformes (1)'!D226 -> 6 | E6: =+'TablasInformes (1)'!E226 -> 8 | F6: =+'TablasInformes (1)'!F226 -> 12 | G6: =+'TablasInformes (1)'!G226 -> 6 | H6: =+'TablasInformes (1)'!H226 -> 8
B7: Francia | C7: =+'TablasInformes (1)'!C227 -> 11 | D7: =+'TablasInformes (1)'!D227 -> 6 | E7: =+'TablasInformes (1)'!E227 -> 8 | F7: =+'TablasInformes (1)'!F227 -> 12 | G7: =+'TablasInformes (1)'!G227 -> 6 | H7: =+'TablasInformes (1)'!H227 -> 8
B8: Italia | C8: =+'TablasInformes (1)'!C228 -> 12 | D8: =+'TablasInformes (1)'!D228 -> 6 | E8: =+'TablasInformes (1)'!E228 -> 8 | F8: =+'TablasInformes (1)'!F228 -> 12 | G8: =+'TablasInformes (1)'!G228 -> 6 | H8: =+'TablasInformes (1)'!H228 -> 8
B9: Centro Europa | C9: =+'TablasInformes (1)'!C229 -> 12 | D9: =+'TablasInformes (1)'!D229 -> 6 | E9: =+'TablasInformes (1)'!E229 -> 8 | F9: =+'TablasInformes (1)'!F229 -> 12 | G9: =+'TablasInformes (1)'!G229 -> 6 | H9: =+'TablasInformes (1)'!H229 -> 8
B10: Polonia | C10: =+'TablasInformes (1)'!C230 -> 12 | D10: =+'TablasInformes (1)'!D230 -> 6 | E10: =+'TablasInformes (1)'!E230 -> 8 | F10: =+'TablasInformes (1)'!F230 -> 12 | G10: =+'TablasInformes (1)'!G230 -> 6 | H10: =+'TablasInformes (1)'!H230 -> 8
B11: Mexico | C11: =+'TablasInformes (1)'!C231 -> 12 | D11: =+'TablasInformes (1)'!D231 -> 6 | E11: =+'TablasInformes (1)'!E231 -> 8 | F11: =+'TablasInformes (1)'!F231 -> 12 | G11: =+'TablasInformes (1)'!G231 -> 6 | H11: =+'TablasInformes (1)'!H231 -> 8
A12: FreshMarket | B12: Espana | C12: =+'TablasInformes (1)'!C232 -> 12 | D12: =+'TablasInformes (1)'!D232 -> 6 | E12: =+'TablasInformes (1)'!E232 -> 8 | F12: =+'TablasInformes (1)'!F232 -> 12 | G12: =+'TablasInformes (1)'!G232 -> 6 | H12: =+'TablasInformes (1)'!H232 -> 8
B13: Portugal | C13: =+'TablasInformes (1)'!C233 -> 12 | D13: =+'TablasInformes (1)'!D233 -> 6 | E13: =+'TablasInformes (1)'!E233 -> 8 | F13: =+'TablasInformes (1)'!F233 -> 12 | G13: =+'TablasInformes (1)'!G233 -> 6 | H13: =+'TablasInformes (1)'!H233 -> 8
B14: Francia | C14: =+'TablasInformes (1)'!C234 -> 12 | D14: =+'TablasInformes (1)'!D234 -> 6 | E14: =+'TablasInformes (1)'!E234 -> 8 | F14: =+'TablasInformes (1)'!F234 -> 12 | G14: =+'TablasInformes (1)'!G234 -> 6 | H14: =+'TablasInformes (1)'!H234 -> 8
B15: Italia | C15: =+'TablasInformes (1)'!C235 -> 12 | D15: =+'TablasInformes (1)'!D235 -> 6 | E15: =+'TablasInformes (1)'!E235 -> 8 | F15: =+'TablasInformes (1)'!F235 -> 12 | G15: =+'TablasInformes (1)'!G235 -> 6 | H15: =+'TablasInformes (1)'!H235 -> 8
B16: Centro Europa | C16: =+'TablasInformes (1)'!C236 -> 12 | D16: =+'TablasInformes (1)'!D236 -> 6 | E16: =+'TablasInformes (1)'!E236 -> 8 | F16: =+'TablasInformes (1)'!F236 -> 12 | G16: =+'TablasInformes (1)'!G236 -> 6 | H16: =+'TablasInformes (1)'!H236 -> 8
B17: Polonia | C17: =+'TablasInformes (1)'!C237 -> 12 | D17: =+'TablasInformes (1)'!D237 -> 6 | E17: =+'TablasInformes (1)'!E237 -> 8 | F17: =+'TablasInformes (1)'!F237 -> 12 | G17: =+'TablasInformes (1)'!G237 -> 6 | H17: =+'TablasInformes (1)'!H237 -> 8
B18: Mexico | C18: =+'TablasInformes (1)'!C238 -> 12 | D18: =+'TablasInformes (1)'!D238 -> 6 | E18: =+'TablasInformes (1)'!E238 -> 8 | F18: =+'TablasInformes (1)'!F238 -> 12 | G18: =+'TablasInformes (1)'!G238 -> 6 | H18: =+'TablasInformes (1)'!H238 -> 8
A19: SparklingCo | B19: Espana | C19: =+'TablasInformes (1)'!C239 -> 10 | D19: =+'TablasInformes (1)'!D239 -> 4 | E19: =+'TablasInformes (1)'!E239 -> 8 | F19: =+'TablasInformes (1)'!F239 -> 11 | G19: =+'TablasInformes (1)'!G239 -> 4 | H19: =+'TablasInformes (1)'!H239 -> 8
B20: Portugal | C20: =+'TablasInformes (1)'!C240 -> 10 | D20: =+'TablasInformes (1)'!D240 -> 4 | E20: =+'TablasInformes (1)'!E240 -> 8 | F20: =+'TablasInformes (1)'!F240 -> 11 | G20: =+'TablasInformes (1)'!G240 -> 4 | H20: =+'TablasInformes (1)'!H240 -> 8
B21: Francia | C21: =+'TablasInformes (1)'!C241 -> 10 | D21: =+'TablasInformes (1)'!D241 -> 4 | E21: =+'TablasInformes (1)'!E241 -> 8 | F21: =+'TablasInformes (1)'!F241 -> 11 | G21: =+'TablasInformes (1)'!G241 -> 4 | H21: =+'TablasInformes (1)'!H241 -> 8
B22: Italia | C22: =+'TablasInformes (1)'!C242 -> 10 | D22: =+'TablasInformes (1)'!D242 -> 4 | E22: =+'TablasInformes (1)'!E242 -> 8 | F22: =+'TablasInformes (1)'!F242 -> 11 | G22: =+'TablasInformes (1)'!G242 -> 4 | H22: =+'TablasInformes (1)'!H242 -> 8
B23: Centro Europa | C23: =+'TablasInformes (1)'!C243 -> 10 | D23: =+'TablasInformes (1)'!D243 -> 4 | E23: =+'TablasInformes (1)'!E243 -> 8 | F23: =+'TablasInformes (1)'!F243 -> 11 | G23: =+'TablasInformes (1)'!G243 -> 4 | H23: =+'TablasInformes (1)'!H243 -> 8
B24: Polonia | C24: =+'TablasInformes (1)'!C244 -> 10 | D24: =+'TablasInformes (1)'!D244 -> 4 | E24: =+'TablasInformes (1)'!E244 -> 8 | F24: =+'TablasInformes (1)'!F244 -> 11 | G24: =+'TablasInformes (1)'!G244 -> 4 | H24: =+'TablasInformes (1)'!H244 -> 8
B25: Mexico | C25: =+'TablasInformes (1)'!C245 -> 10 | D25: =+'TablasInformes (1)'!D245 -> 4 | E25: =+'TablasInformes (1)'!E245 -> 8 | F25: =+'TablasInformes (1)'!F245 -> 11 | G25: =+'TablasInformes (1)'!G245 -> 4 | H25: =+'TablasInformes (1)'!H245 -> 8
A26: QualityMax | B26: Espana | C26: =+'TablasInformes (1)'!C246 -> 9 | D26: =+'TablasInformes (1)'!D246 -> 4 | E26: =+'TablasInformes (1)'!E246 -> 6 | F26: =+'TablasInformes (1)'!F246 -> 11 | G26: =+'TablasInformes (1)'!G246 -> 6 | H26: =+'TablasInformes (1)'!H246 -> 7
B27: Portugal | C27: =+'TablasInformes (1)'!C247 -> 9 | D27: =+'TablasInformes (1)'!D247 -> 4 | E27: =+'TablasInformes (1)'!E247 -> 6 | F27: =+'TablasInformes (1)'!F247 -> 11 | G27: =+'TablasInformes (1)'!G247 -> 6 | H27: =+'TablasInformes (1)'!H247 -> 7
B28: Francia | C28: =+'TablasInformes (1)'!C248 -> 9 | D28: =+'TablasInformes (1)'!D248 -> 4 | E28: =+'TablasInformes (1)'!E248 -> 6 | F28: =+'TablasInformes (1)'!F248 -> 11 | G28: =+'TablasInformes (1)'!G248 -> 6 | H28: =+'TablasInformes (1)'!H248 -> 7
B29: Italia | C29: =+'TablasInformes (1)'!C249 -> 9 | D29: =+'TablasInformes (1)'!D249 -> 4 | E29: =+'TablasInformes (1)'!E249 -> 5 | F29: =+'TablasInformes (1)'!F249 -> 11 | G29: =+'TablasInformes (1)'!G249 -> 6 | H29: =+'TablasInformes (1)'!H249 -> 7
B30: Centro Europa | C30: =+'TablasInformes (1)'!C250 -> 5 | D30: =+'TablasInformes (1)'!D250 -> 3 | E30: =+'TablasInformes (1)'!E250 -> 5 | F30: =+'TablasInformes (1)'!F250 -> 11 | G30: =+'TablasInformes (1)'!G250 -> 6 | H30: =+'TablasInformes (1)'!H250 -> 7
B31: Polonia | C31: =+'TablasInformes (1)'!C251 -> 7 | D31: =+'TablasInformes (1)'!D251 -> 4 | E31: =+'TablasInformes (1)'!E251 -> 5 | F31: =+'TablasInformes (1)'!F251 -> 11 | G31: =+'TablasInformes (1)'!G251 -> 6 | H31: =+'TablasInformes (1)'!H251 -> 7
B32: Mexico | C32: =+'TablasInformes (1)'!C252 -> 9 | D32: =+'TablasInformes (1)'!D252 -> 4 | E32: =+'TablasInformes (1)'!E252 -> 5 | F32: =+'TablasInformes (1)'!F252 -> 11 | G32: =+'TablasInformes (1)'!G252 -> 6 | H32: =+'TablasInformes (1)'!H252 -> 7
A33: Drink2Go | B33: Espana | C33: =+'TablasInformes (1)'!C253 -> 10 | D33: =+'TablasInformes (1)'!D253 -> 5 | E33: =+'TablasInformes (1)'!E253 -> 8 | F33: =+'TablasInformes (1)'!F253 -> 11 | G33: =+'TablasInformes (1)'!G253 -> 6 | H33: =+'TablasInformes (1)'!H253 -> 8
B34: Portugal | C34: =+'TablasInformes (1)'!C254 -> 10 | D34: =+'TablasInformes (1)'!D254 -> 5 | E34: =+'TablasInformes (1)'!E254 -> 8 | F34: =+'TablasInformes (1)'!F254 -> 11 | G34: =+'TablasInformes (1)'!G254 -> 6 | H34: =+'TablasInformes (1)'!H254 -> 8
B35: Francia | C35: =+'TablasInformes (1)'!C255 -> 10 | D35: =+'TablasInformes (1)'!D255 -> 5 | E35: =+'TablasInformes (1)'!E255 -> 8 | F35: =+'TablasInformes (1)'!F255 -> 11 | G35: =+'TablasInformes (1)'!G255 -> 6 | H35: =+'TablasInformes (1)'!H255 -> 8
B36: Italia | C36: =+'TablasInformes (1)'!C256 -> 10 | D36: =+'TablasInformes (1)'!D256 -> 5 | E36: =+'TablasInformes (1)'!E256 -> 8 | F36: =+'TablasInformes (1)'!F256 -> 11 | G36: =+'TablasInformes (1)'!G256 -> 6 | H36: =+'TablasInformes (1)'!H256 -> 8
B37: Centro Europa | C37: =+'TablasInformes (1)'!C257 -> 10 | D37: =+'TablasInformes (1)'!D257 -> 5 | E37: =+'TablasInformes (1)'!E257 -> 5 | F37: =+'TablasInformes (1)'!F257 -> 11 | G37: =+'TablasInformes (1)'!G257 -> 6 | H37: =+'TablasInformes (1)'!H257 -> 8
B38: Polonia | C38: =+'TablasInformes (1)'!C258 -> 10 | D38: =+'TablasInformes (1)'!D258 -> 6 | E38: =+'TablasInformes (1)'!E258 -> 6 | F38: =+'TablasInformes (1)'!F258 -> 11 | G38: =+'TablasInformes (1)'!G258 -> 6 | H38: =+'TablasInformes (1)'!H258 -> 8
B39: Mexico | C39: =+'TablasInformes (1)'!C259 -> 10 | D39: =+'TablasInformes (1)'!D259 -> 6 | E39: =+'TablasInformes (1)'!E259 -> 7 | F39: =+'TablasInformes (1)'!F259 -> 11 | G39: =+'TablasInformes (1)'!G259 -> 6 | H39: =+'TablasInformes (1)'!H259 -> 8

Sheet 13, 14 y 15
A1: 13
A2: Priorizacion segmentos de demanda. Drink2Go
B3: =+'TablasInformes (1)'!B263 -> 2023 | C3: =+'TablasInformes (1)'!C263 -> 2024 | D3: =+'TablasInformes (1)'!D263 -> 2025 | E3: =+'TablasInformes (1)'!E263 -> 2026 | F3: =+'TablasInformes (1)'!F263 -> 2027 | G3: =+'TablasInformes (1)'!G263 -> 2028
A4: Jovenes | B4: =+'TablasInformes (1)'!B265 -> 7 | C4: =+'TablasInformes (1)'!C265 -> 4 | D4: =+'TablasInformes (1)'!D265 -> 4 | E4: =+'TablasInformes (1)'!E265 -> 4 | F4: =+'TablasInformes (1)'!F265 -> 4 | G4: =+'TablasInformes (1)'!G265 -> 4
A5: Adultos | B5: =+'TablasInformes (1)'!B266 -> 7 | C5: =+'TablasInformes (1)'!C266 -> 8 | D5: =+'TablasInformes (1)'!D266 -> 8 | E5: =+'TablasInformes (1)'!E266 -> 8 | F5: =+'TablasInformes (1)'!F266 -> 8 | G5: =+'TablasInformes (1)'!G266 -> 8
A6: Deportistas | B6: =+'TablasInformes (1)'!B267 -> 7 | C6: =+'TablasInformes (1)'!C267 -> 9 | D6: =+'TablasInformes (1)'!D267 -> 9 | E6: =+'TablasInformes (1)'!E267 -> 9 | F6: =+'TablasInformes (1)'!F267 -> 9 | G6: =+'TablasInformes (1)'!G267 -> 9
A16: 14
A19: Gasto en marca por producto. Drink2Go
B20: =+'TablasInformes (1)'!B271 -> 2023 | C20: =+'TablasInformes (1)'!C271 -> 2024 | D20: =+'TablasInformes (1)'!D271 -> 2025 | E20: =+'TablasInformes (1)'!E271 -> 2026 | F20: =+'TablasInformes (1)'!F271 -> 2027 | G20: =+'TablasInformes (1)'!G271 -> 2028
